Workbook

Sheet Version
B3: Version | C3: Detail | D3: start date
B4: 1 | C4: Create test scenario & test case based from FRS only. | D4: 46118
B5: 2 | C5: Update test scenario & test case based from demo | D5: 46127

Sheet Todo List
K4: TestCase
M5: UserAccountAccess&Validation | N5: Only Add TC title need to complete the rest
M6: Search
M7: Product Comparison
M8: AddToCart
M9: WishList
M10: Checkout | N10: blocked on payment method
M11: AccountFeature
M12: Footer Feature
K16: Defect | N16: Need formatting
N17: Need to add details,picture reference on defect

Sheet Defect
A4: Defect ID | B4: Detected Date | C4: Description/Summary | D4: Step to Reproduce | E4: Expected Result | F4: Actual Result | G4: Severity | H4: Priority | I4: Screenshot | J4: Status
A5: Def-001 | B5: =DATE(2026,4,20) -> 46132 | C5: frequently 522 response | D5: 1. open application URL | E5: User enter homepage | F5: 522 error | G5: Critical | H5: P0 (High) | I5: =_xlfn.DISPIMG("ID_DCD6BF44FE934B62BEF4AF54A6DF501A",1) -> =DISPIMG("ID_DCD6BF44FE934B62BEF4AF54A6DF501A",1) | J5: Occasionaly occurs
A6: Def-002 | B6: =DATE(2026,4,20) -> 46132 | C6: All product is out of stock | D6: 1. open application URL 2. add product to cart 3. proceed to checkout 4. set quantity to 1 or more 5. click checkout | E6: proceed to checkout page | F6: no single item available to proceed | G6: low | H6: P0 (High) | I6: =_xlfn.DISPIMG("ID_BA59952DF61247A7B7CF088F37895BD1",1) -> =DISPIMG("ID_BA59952DF61247A7B7CF088F37895BD1",1) | J6: fixed
A7: Def-003 | B7: 46132 | C7: Need letter limitation | D7: 1. open application URL 2. Input long text to search tab 3. click search | E7: should not accept long input which can cause stress to server | F7: Always accept user input and conduct searches, but occasionally limit the search function for a set time period. | G7: low | H7: low | J7: found
A8: Def-004 | B8: 46135 | C8: No payment available | D8: 1. open application 2. login 3. add product to cart 4. check out 5. select payment method | E8: have selectable list of payment method available | F8: got error message,no available payment method can not continue transaction | G8: Critical | H8: P0 (High) | I8: =_xlfn.DISPIMG("ID_5AE021B245F644E3960B009A03D090E8",1) -> =DISPIMG("ID_5AE021B245F644E3960B009A03D090E8",1) | J8: found
A9: Def-005 | B9: 46135 | C9: nothing happen after click choose payment method when not logged in | D9: 1. open application 2. add product to cart 3. check out 4. select payment method | E9: have selectable list of payment method available | F9: not thing happen | G9: high | H9: P0 (High) | I9: =_xlfn.DISPIMG("ID_D5E4F8FF524944B6A0BD069F07AF88C0",1) -> =DISPIMG("ID_D5E4F8FF524944B6A0BD069F07AF88C0",1) | J9: found
A10: Def-006 | B10: 46135 | C10: when added out of stock item to cart on wish list + show error message | D10: 1. open application 2. add out of stock product to wish list 3. open wish list page 4. click add to cart button on added product | E10: should not be able product to cart / not shown error message | F10: successfully added product to cart and have error message appear

Sheet RTM
A1: Traceablility Matrix
A6: Req. ID | B6: Req Desc | C6: Scenario | D6: TC ID | E6: TC Desc | F6: Test Result | G6: Defect Id | H6: Defect Status

Sheet Scenario
A1: Open Cart Frontend
A2: URL | B2: https://demo.opencart.com/
A3: Requirement | B3: https://drive.google.com/drive/folders/1nBs25k9jTb06qrV-5fTC75gtPOR6uW4V
B4: * 1.0 create test scenario/test case only from FRS only
A9: Test Scenario ID | B9: Reference | C9: Test Scenario Description | D9: Priority | E9: Number of Test Cases | F9: defect | G9: Note
A10: TS001 | B10: Demo | C10: Validate the working of 'Register an account' functionality | D10: P0 | E10: =COUNTIF('UserAccountAccess&Validation'!B:B,"*TS001*") -> 26 | F10: =COUNTIFS('UserAccountAccess&Validation'!J:J,"defect",'UserAccountAccess&Validation'!B:B,"%TS001%") -> 0
A11: TS002 | B11: Demo | C11: Validate the working of 'Login' functionality | D11: P0 | E11: =COUNTIF('UserAccountAccess&Validation'!B:B,"*TS002*") -> 15 | F11: =COUNTIFS('UserAccountAccess&Validation'!J:J,"defect",'UserAccountAccess&Validation'!B:B,"%TS002%") -> 0
A12: TS003 | B12: Demo | C12: Validate the working of 'Logout' functionality | D12: P0 | E12: =COUNTIF('UserAccountAccess&Validation'!B:B,"*TS003*") -> 2 | F12: =COUNTIFS('UserAccountAccess&Validation'!J:J,"defect",'UserAccountAccess&Validation'!B:B,"%TS003%") -> 0
A13: TS004 | B13: Demo | C13: Validate the working of 'Forgot Password' functionality | D13: P2 | E13: =COUNTIF('UserAccountAccess&Validation'!B:B,"*TS004*") -> 7 | F13: =COUNTIFS('UserAccountAccess&Validation'!J:J,"defect",'UserAccountAccess&Validation'!B:B,"%TS004%") -> 0
A14: TS005 | B14: FRS | C14: Validate the working of 'Search' functionality | D14: P1 | E14: =COUNTIF(Search!B:B,"*TS005*") -> 23 | F14: =COUNTIF(Search!J3:J10006,"Defect") -> 0
A15: TS006 | B15: FRS | C15: Validate the working of 'Product compare' functionality | D15: P2 | E15: =COUNTIF('Product Comparison'!B:B,"*TS006*") -> 7 | F15: =COUNTIF('Product Comparison'!J3:J9999,"Defect") -> 0
A16: TS007 | B16: FRS | C16: Validate the working of 'Product page' functionality | D16: P1 | E16: =COUNTIF('Product Pages'!B2:B201,"*TS007*") -> 30 | F16: =COUNTIF('Product Pages'!J2:J9998,"Defect") -> 0
A17: TS008 | B17: FRS | C17: Validate the working of 'Add to cart' functionality | D17: P1 | E17: =COUNTA(AddToCart!A3:A202) -> 10 | F17: =COUNTIF(AddToCart!J3:J9999,"Defect") -> 1
A18: TS009 | B18: FRS | C18: Validate the working of 'Wish List' option | D18: P4 | E18: =COUNTA(WishList!B:B) -> 11 | F18: =COUNTIF(WishList!J1:J10004,"Defect") -> 2
A19: TS010 | B19: FRS | C19: Validate the working of 'Shopping Cart page' functionality | D19: P1 | E19: =COUNTA('Shopping Cart page'!A1:A1007) -> 36 | F19: =COUNTIF('Shopping Cart page'!J2:J9998,"Defect") -> 0
A20: TS011 | B20: FRS | C20: Validate the working of 'Home page' functionality | D20: P2 | E20: =COUNTA(HomePage!A2:A9997) -> 11 | F20: =COUNTIF(HomePage!J2:J9998,"Defect") -> 0
A21: TS012 | B21: FRS | C21: Validate the working of 'Checkout' functionality | D21: P1 | E21: =COUNTA(Checkout!A2:A10052) -> 66 | F21: =COUNTIF(Checkout!J2:J10052,"defect") -> 0
A22: TS013 | B22: Demo | C22: Validate the working of 'My Account' functionality | D22: P3 | E22: =COUNTIF(UserFeature!B:B,"*TS013*") -> 2
A23: TS014 | B23: Demo | C23: Validate the working of 'My Account > Account Information' functionality | D23: P3 | E23: =COUNTIF(UserFeature!B:B,"*TS014*") -> 19
A24: TS015 | B24: Demo | C24: Validate the working of 'My Account > Change Password' functionality | D24: P3 | E24: =COUNTIF(UserFeature!B:B,"*TS015*") -> 17
A25: TS016 | B25: Demo | C25: Validate the working of 'My Account Address Book' functionality | D25: P3 | E25: =COUNTIF(UserFeature!B:B,"*TS016*") -> 66
A26: TS017 | B26: Demo | C26: Validate the working of 'My Order > Order History' functionality | D26: P3
A27: TS018 | B27: Demo | C27: Validate the working of 'My Orders > Order Information' functionality | D27: P3
A28: TS019 | B28: Demo | C28: Validate the working of 'My Orders > Product Returns' functionality | D28: P3
A29: TS020 | B29: Demo | C29: Validate the working of 'My Order > Downloads' functionality | D29: P3
A30: TS021 | B30: Demo | C30: Validate the working of 'My Orders > Reward Points' functionality | D30: P3
A31: TS022 | B31: Demo | C31: Validate the working of 'My Orders > Returned Request' functionality | D31: P3
A32: TS023 | B32: Demo | C32: Validate the working of 'My Order > Your Transactions' functionality | D32: P3
A33: TS024 | B33: Demo | C33: Validate the working of 'My Order > Recurring Payments' functionality | D33: P3
A34: TS025 | B34: FRS | C34: Validate the working of 'Affiliate' functionality | D34: P4
A35: TS026 | B35: FRS | C35: Validate the working of 'Newsletter' functionality | D35: P4
A36: TS027 | B36: FRS | C36: Validate the working of 'Contact Us' functionality | D36: P4
A37: TS028 | B37: FRS | C37: Validate the working of 'Gift' functionality | D37: P4
A38: TS029 | B38: FRS | C38: Validate the working of 'Special Offer' functionality | D38: P4
A39: TS030 | B39: FRS | C39: Validate the working of 'Header' options' functionality | D39: P4 | E39: =COUNTA(Header!A2:A204) -> 26 | F39: =COUNTIF(Header!J2:J10003,"Defect") -> 0
A40: TS031 | B40: FRS | C40: Validate the working of 'Top Menu' options' functionality | D40: P4 | E40: =COUNTA('Top Menu'!A2:A200) -> 5 | F40: =COUNTIF('Top Menu'!J2:J9998,"defect") -> 0
A41: TS032 | B41: FRS | C41: Validate the working of 'Footer' options' functionality | D41: P4 | E41: =COUNTA(Footer!A2:A199) -> 16 | F41: =COUNTIF(Footer!J2:J9998,"defect") -> 0
A42: TS033 | B42: FRS | C42: Validate the Application functionality for different currency | D42: P2 | E42: =COUNTA(Currency!A2:A199) -> 2 | F42: =COUNTIF(Currency!J2:J9998,"defect") -> 0
D43: Total = | E43: =SUM(E10:E42) -> 397

Sheet UserAccountAccess&Validation
A1: Test Case ID | B1: Test Scenario | C1: Test Case Title | D1: Pre-requisites | E1: Test Steps | F1: Test Data | G1: Expected Result (ER) | H1: Actual Result | I1: Priority | J1: Result | K1: Comments
A2: TC_ACC_001 | B2: =_xlfn.TEXTJOIN(CHAR(10),,Scenario!A11,Scenario!C11) -> TS002 Validate the working of 'Login' functionality | C2: Validate login - structure | D2: Open application, enter login page | E2: 1. Validate result (ER-1) | F2: Not applicable | G2: Page should contain header,new customer section,login section, account sub-menu section
A3: TC_ACC_002 | B3: =_xlfn.TEXTJOIN(CHAR(10),,Scenario!A11,Scenario!C11) -> TS002 Validate the working of 'Login' functionality | C3: Validate user - access - header | D3: Open application,On any page of the application | E3: 1. Click my account on header 2. Click Login button 3. Validate result (ER-1) | F3: Not applicable | G3: Should redirect user to account page
A4: TC_ACC_003 | B4: =_xlfn.TEXTJOIN(CHAR(10),,Scenario!A11,Scenario!C11) -> TS002 Validate the working of 'Login' functionality | C4: Validate login - access - check out | D4: Open application, added item to cart, proceed to checkout, not logged in | E4: 1. Click 'check out' button 2. Validate result (ER-1) 3. Click login link on message 4. Validate result (ER-2) | F4: Not applicable | G4: 1. Should show message "please login or create an account before continue" 2. Should redirect user to account page
A5: TC_ACC_004 | B5: =_xlfn.TEXTJOIN(CHAR(10),,Scenario!A11,Scenario!C11) -> TS002 Validate the working of 'Login' functionality | C5: Validate login - access - wish list | D5: Open application,not logged in | E5: 1. Select item to add to wish list -<Refer test data> 2. Validate message (ER-1) 3. Click login link on message 4. Validate result (ER-2) | F5: Product : iMac | G5: 1. Should show message "You must login or create an account to save "iMac" to your wish list! " 2. Should redirect user to login page
A6: TC_ACC_005 | B6: =_xlfn.TEXTJOIN(CHAR(10),,Scenario!A11,Scenario!C11) -> TS002 Validate the working of 'Login' functionality | C6: Validate Login - email required field | D6: Open application, enter login page | E6: 1. Click 'log in' button 2. Validate result (ER-1),(ER-2) | F6: Not applicable | G6: 1. Should not accept input and return with warning "Warning : please enter an email" 2. should show " * " symbol after text "email" | H6: Accept null data and continue the process Result in " Warning: No match for E-Mail Address and/or Password." Have correct symbol shown
A7: TC_ACC_006 | B7: =_xlfn.TEXTJOIN(CHAR(10),,Scenario!A11,Scenario!C11) -> TS002 Validate the working of 'Login' functionality | C7: Validate Login - email valid | D7: Open application, enter login page | E7: 1. Enter an email -<Refer test data> 2. Click 'log in' button 3. Validate result (ER-1) | F7: email : test@gmail.com | G7: Should accept test data and check with backend
A8: TC_ACC_007 | B8: =_xlfn.TEXTJOIN(CHAR(10),,Scenario!A11,Scenario!C11) -> TS002 Validate the working of 'Login' functionality | C8: Validate Login - email wrong format | D8: Open application, enter login page | E8: 1. enter an email -<Refer test data> 2. Click 'log in' button 3. Validate result (ER-1) | F8: email: test_gmail.com | G8: Should not accept data and return with warning | H8: Accept data and continue the process
A9: TC_ACC_008 | B9: =_xlfn.TEXTJOIN(CHAR(10),,Scenario!A11,Scenario!C11) -> TS002 Validate the working of 'Login' functionality | C9: Validate Login - email boundary - below | D9: Open application, enter login page | E9: 1. enter an email -<Refer test data> 2. Click 'log in' button 3. Validate result (ER-1) | F9: email : any input that below 4 characters | G9: accept when input is at least 6 characters | H9: Accept data and continue the process | K9: Should only accept 4-20 characters input
A10: TC_ACC_009 | B10: =_xlfn.TEXTJOIN(CHAR(10),,Scenario!A11,Scenario!C11) -> TS002 Validate the working of 'Login' functionality | C10: Validate Login - email boundary - above | D10: Open application, enter login page | E10: 1. enter an email -<Refer test data> 2. Click 'log in' button 3. Validate result (ER-1) | F10: email : any input that over 255 characters | G10: do not accept when input is over 254 characters input | H10: Accept data and continue the process | K10: Should only accept 4-20 characters input
A11: TC_ACC_010 | B11: =_xlfn.TEXTJOIN(CHAR(10),,Scenario!A12,Scenario!C12) -> TS003 Validate the working of 'Logout' functionality | C11: Validate Login - password required field | D11: Open application, enter login page | E11: 1. Click 'log in' button 2. Validate result (ER-1) | F11: Not applicable | G11: Should not accept input and return with warning "Warning : please enter a password" | H11: Accept null data and continue the process Result in " Warning: No match for E-Mail Address and/or Password."
A12: TC_ACC_011 | B12: =_xlfn.TEXTJOIN(CHAR(10),,Scenario!A11,Scenario!C11) -> TS002 Validate the working of 'Login' functionality | C12: Validate Login - password valid | D12: Open application, enter login page | E12: 1. Enter password -<Refer test data> 2. Click 'log in' button 3. Validate result (ER-1) | F12: password : test | G12: Should accept the password
A13: TC_ACC_012 | B13: =_xlfn.TEXTJOIN(CHAR(10),,Scenario!A11,Scenario!C11) -> TS002 Validate the working of 'Login' functionality | C13: Validate Login - password invalid | D13: Open application, enter login page | E13: 1. Enter password -<Refer test data> 2. Click 'log in' button 3. Validate result (ER-1) | F13: password : รหัสผ่าน | G13: Should not accept the password and return with warning "Warning: No match for E-Mail Address and/or Password." | H13: Did not accept the password and return correct warning
A14: TC_ACC_013 | B14: =_xlfn.TEXTJOIN(CHAR(10),,Scenario!A11,Scenario!C11) -> TS002 Validate the working of 'Login' functionality | C14: Validate Login - password boundary - below | D14: Open application, enter login page | E14: 1. Enter password -<Refer test data> 2. Click 'log in' button 3. Validate result (ER-1) | F14: password : pas | G14: Should not accept the password but still return with warning "Warning: No match for E-Mail Address and/or Password." | H14: Did not accept the password and return correct warning
A15: TC_ACC_014 | B15: =_xlfn.TEXTJOIN(CHAR(10),,Scenario!A11,Scenario!C11) -> TS002 Validate the working of 'Login' functionality | C15: Validate Login - password boundary - above | D15: Open application, enter login page | E15: 1. Enter password -<Refer test data> 2. Click 'log in' button 3. Validate result (ER-1) | F15: password : any mixed characters that over 50 characters | G15: Should not accept the password but still return with warning "Warning: No match for E-Mail Address and/or Password." | H15: Did not accept the password and return correct warning
A16: TC_ACC_015 | B16: =_xlfn.TEXTJOIN(CHAR(10),,Scenario!A11,Scenario!C11) -> TS002 Validate the working of 'Login' functionality | C16: Validate Login - pass | D16: Open application, enter login page | E16: 1. Enter email&password -<Refer test data> 2. Click 'log in' button 3. Validate result (ER-1) | F16: email : test@gmail.com password : test | G16: User should redirect to user page
A17: TC_ACC_016 | B17: =_xlfn.TEXTJOIN(CHAR(10),,Scenario!A11,Scenario!C11) -> TS002 Validate the working of 'Login' functionality | C17: Validate Login - fail | D17: Open application, enter login page | E17: 1. Enter email&password -<Refer test data> 2. Click 'log in' button 3. Validate result (ER-1) | F17: email : test@gmail.com password : test1234 | G17: Should fail the login and return with warning "Warning: No match for E-Mail Address and/or Password." | H17: Did not pass the login and return with correct warning
A18: TC_ACC_017 | B18: =_xlfn.TEXTJOIN(CHAR(10),,Scenario!$A$10,Scenario!$C$10) -> TS001 Validate the working of 'Register an account' functionality | C18: Validate Register - access - header | D18: Open application, enter register page | E18: 1. Click my account on header 2. Click register button 3. Validate result (ER-1) | F18: Not applicable | G18: Should redirect user to register page
A19: TC_ACC_018 | B19: =_xlfn.TEXTJOIN(CHAR(10),,Scenario!$A$10,Scenario!$C$10) -> TS001 Validate the working of 'Register an account' functionality | C19: Validate Register - access - wish list | D19: Open application,not logged in | E19: 1. Select item to add to wish list -<Refer test data> 2. Validate message (ER-1) 3. Click register link on message 4. Validate result (ER-2) | F19: Product : iMac | G19: 1. Should show message "You must login or create an account to save "iMac" to your wish list! " 2. Should redirect user to login page
A20: TC_ACC_019 | B20: =_xlfn.TEXTJOIN(CHAR(10),,Scenario!$A$10,Scenario!$C$10) -> TS001 Validate the working of 'Register an account' functionality | C20: Validate Register - access - check out | D20: Open application, added item to cart, proceed to checkout, not logged in | E20: 1. Click 'check out' button 2. Validate result (ER-1) | F20: Not applicable | G20: Should redirect user to register page
A21: TC_ACC_020 | B21: =_xlfn.TEXTJOIN(CHAR(10),,Scenario!$A$10,Scenario!$C$10) -> TS001 Validate the working of 'Register an account' functionality | C21: Validate Register - page structure | D21: Open application, enter register page | E21: 1. Validate result (ER-1) | F21: Not applicable | G21: Page should contain these element : Firstname, lastname, email,password,newsletter subscribtion,privacy policy agreement continue button
A22: TC_ACC_021 | B22: =_xlfn.TEXTJOIN(CHAR(10),,Scenario!$A$10,Scenario!$C$10) -> TS001 Validate the working of 'Register an account' functionality | C22: Validate Register - first name - required field | D22: Open application, enter register page | E22: 1. Click continue 2. Validate result (ER-1) | F22: Not applicable | G22: Should show error message "Please enter your first name" under first name field. first name fieldhave " * " mark at the end of first name
A23: TC_ACC_022 | B23: =_xlfn.TEXTJOIN(CHAR(10),,Scenario!$A$10,Scenario!$C$10) -> TS001 Validate the working of 'Register an account' functionality | C23: Validate Register - first name - valid | D23: Open application, enter register page | E23: 1. Enter first name -<Refer test data> 2. Click continue 3. Validate result | F23: first name : sawan | G23: Should accept first name and not show any error under first name field
A24: TC_ACC_023 | B24: =_xlfn.TEXTJOIN(CHAR(10),,Scenario!$A$10,Scenario!$C$10) -> TS001 Validate the working of 'Register an account' functionality | C24: Validate Register - first name - boundary - below | D24: Open application, enter register page | E24: 1. Enter first name -<Refer test data> 2. Click continue 3. Validate result | F24: first name : s | G24: Should not accept first name and show message "first name should be between 4 and 20 characters"
A25: TC_ACC_024 | B25: =_xlfn.TEXTJOIN(CHAR(10),,Scenario!$A$10,Scenario!$C$10) -> TS001 Validate the working of 'Register an account' functionality | C25: Validate Register - first name - boundary - above | D25: Open application, enter register page | E25: 1. Enter first name -<Refer test data> 2. Click continue 3. Validate result | F25: first name : any name that over 20 characters | G25: Should not accept first name and show message "first name should be between 4 and 20 characters"
A26: TC_ACC_025 | B26: =_xlfn.TEXTJOIN(CHAR(10),,Scenario!$A$10,Scenario!$C$10) -> TS001 Validate the working of 'Register an account' functionality | C26: Validate Register - first name - not support characters | D26: Open application, enter register page | E26: 1. Enter first name -<Refer test data> 2. Click continue 3. Validate result | F26: first name : s@wan | G26: Should not accept first name and show message "first name should contain only english characters"
A27: TC_ACC_026 | B27: =_xlfn.TEXTJOIN(CHAR(10),,Scenario!$A$10,Scenario!$C$10) -> TS001 Validate the working of 'Register an account' functionality | C27: Validate Register - last name - require field | D27: Open application, enter register page | E27: 1. Click continue 2. Validate result (ER-1) | F27: Not applicable | G27: Should show error message "Please enter your last name" Under last name fieldhave " * " mark at the end of last name
A28: TC_ACC_027 | B28: =_xlfn.TEXTJOIN(CHAR(10),,Scenario!$A$10,Scenario!$C$10) -> TS001 Validate the working of 'Register an account' functionality | C28: Validate Register - last name - valid | D28: Open application, enter register page | E28: 1. Enter last name -<Refer test data> 2. Click continue 3. Validate result (ER-1) | F28: last name : sumartara | G28: Should accept last name and not show any error message
A29: TC_ACC_028 | B29: =_xlfn.TEXTJOIN(CHAR(10),,Scenario!$A$10,Scenario!$C$10) -> TS001 Validate the working of 'Register an account' functionality | C29: Validate Register - last name - boundary - below | D29: Open application, enter register page | E29: 1. Enter last name -<Refer test data> 2. Click continue 3. Validate result (ER-1) | F29: last name : any name under 4 characters | G29: Should not accept last name under 4 characters
... A43: TC_ACC_043 | B43: =_xlfn.TEXTJOIN(CHAR(10),,Scenario!$A$10,Scenario!$C$10) -> TS001 Validate the working of 'Register an account' functionality | C43: Validate Register - duplicate | D43: Open application, enter login page | E43: 1. Enter all required information 2. Click checkbox 3. Click continue | F43: email : test@gmail.com password : aa1234 | G43: Should successfully register an account,show message "Your email has already used to create and account if you forgot your password please reset password"
A44: TC_ACC_044 | B44: =_xlfn.TEXTJOIN(CHAR(10),,Scenario!A12,Scenario!C12) -> TS003 Validate the working of 'Logout' functionality | C44: Validate user can logout | D44: Open applicationuser already logged in | E44: 1. Click my account on header 2. Click Log out button 3. Validate result (ER-1) | F44: Not applicable | G44: User should logged out
A45: TC_ACC_045 | B45: =_xlfn.TEXTJOIN(CHAR(10),,Scenario!A13,Scenario!C13) -> TS004 Validate the working of 'Forgot Password' functionality | C45: Validate Login - forgot password | D45: Open application, enter login page | E45: 1. Click 'forgot password' button 2. Validate result (ER-1) | F45: Not applicable | G45: User should redirect to reset password page | H45: User edirect to reset password page
A46: TC_ACC_046 | B46: =_xlfn.TEXTJOIN(CHAR(10),,Scenario!A13,Scenario!C13) -> TS004 Validate the working of 'Forgot Password' functionality | C46: Validate Login - forgot password sturcture | D46: Open application, enter reset password page | E46: 1. Validate result (ER-1) | F46: Not applicable | G46: Page should contain header,account sub-menu section, input email for resetting password, go back button,continue button
A47: TC_ACC_047 | B47: =_xlfn.TEXTJOIN(CHAR(10),,Scenario!A13,Scenario!C13) -> TS004 Validate the working of 'Forgot Password' functionality | C47: Validate Login - forgot password successful | D47: Open application, enter reset password page | E47: 1. enter an email -<Refer test data> 2. Click 'continue button 3. Validate result (ER-1) | F47: email : test@gmail.com | G47: Should return message "Resetting password link was sent to your email."
A48: TC_ACC_048 | B48: =_xlfn.TEXTJOIN(CHAR(10),,Scenario!A13,Scenario!C13) -> TS004 Validate the working of 'Forgot Password' functionality | C48: Validate Login - forgot password invalid email | D48: Open application, enter reset password page | E48: 1. enter an email -<Refer test data> 2. Click 'continue button 3. Validate result (ER-1) | F48: email : เทส_gmail.com | G48: Should return message "Please enter valid email"
A49: TC_ACC_049 | B49: =_xlfn.TEXTJOIN(CHAR(10),,Scenario!A13,Scenario!C13) -> TS004 Validate the working of 'Forgot Password' functionality | C49: Validate Login - forgot password required field email | D49: Open application, enter reset password page | E49: 1. Click 'continue button 2. Validate result (ER-1) | F49: Not applicable | G49: Should return message "Please enter an email" have * mark next to email as in "email*"
A50: TC_ACC_050 | B50: =_xlfn.TEXTJOIN(CHAR(10),,Scenario!A13,Scenario!C13) -> TS004 Validate the working of 'Forgot Password' functionality | C50: Validate Login - forgot password not exists email | D50: Open application, enter reset password page | E50: 1. enter an email -<Refer test data> 2. Click 'continue button 3. Validate result (ER-1) | F50: email : test3@gmail.com | G50: Should return message "This email is not registered with this application"
A51: TC_ACC_051 | B51: =_xlfn.TEXTJOIN(CHAR(10),,Scenario!A13,Scenario!C13) -> TS004 Validate the working of 'Forgot Password' functionality | C51: Validate Login - forgot password go back button | D51: Open application, enter reset password page | E51: 1. click "back" button 2. Validate result (ER-1) | F51: Not applicable | G51: Should return to login page

Sheet UserFeature
A1: Test Case ID | B1: Test Scenario | C1: Test Case Title | D1: Pre-requisites | E1: Test Steps | F1: Test Data | G1: Expected Result (ER) | H1: Actual Result | I1: Priority | J1: Result | K1: Comments
A2: TC_ACF_001 | B2: =_xlfn.TEXTJOIN(CHAR(10),,Scenario!$A$22,Scenario!$C$22) -> TS013 Validate the working of 'My Account' functionality | C2: Validate account features | D2: Open application,logged in | E2: 1. Click 'my account' on header 2. Click 'my account' option 3. Validate result (Validate ER-1) | F2: Not applicable | G2: Account page should have following function by section : My Account : edit account information, change password, modify address book entries, modify wish list My Orders : view order history, subscribtion, downlaods,reward points,return request, transaction My Affiliate Account : register for affiliate account News letter : subscribe/unsubscibe Shortcut for quick access on all listed features on right side
A3: TC_ACF_002 | B3: =_xlfn.TEXTJOIN(CHAR(10),,Scenario!$A$22,Scenario!$C$22) -> TS013 Validate the working of 'My Account' functionality | C3: Validate quick access features | D3: Open application,logged in,location is on any account page | E3: 1. Validate result (Validate ER-1) | F3: Not applicable | G3: Should show quick access on right side of the page for navigate through account features
A4: TC_ACF_003 | B4: =_xlfn.TEXTJOIN(CHAR(10),,Scenario!$A$23,Scenario!$C$23) -> TS014 Validate the working of 'My Account > Account Information' functionality | C4: Validate account information link - main | D4: Open application,logged in,enter my account page | E4: 1. Click 'edit your account information' link below my account 2. Validate result (Validate ER-1) | F4: Not applicable | G4: Should navigate user to account information page
A5: TC_ACF_004 | B5: =_xlfn.TEXTJOIN(CHAR(10),,Scenario!$A$23,Scenario!$C$23) -> TS014 Validate the working of 'My Account > Account Information' functionality | C5: Validate account information link - quick access | D5: Open application,logged in,location is on any account page | E5: 1. Click 'edit your account information' link on quick access 2. Validate result (Validate ER-1) | F5: Not applicable | G5: Should navigate user to account information page
A6: TC_ACF_005 | B6: =_xlfn.TEXTJOIN(CHAR(10),,Scenario!$A$23,Scenario!$C$23) -> TS014 Validate the working of 'My Account > Account Information' functionality | C6: Validate account information - element | D6: Open application,logged in,location is on account information page | E6: 1. Validate result (Validate ER-1) | F6: Not applicable | G6: This page should show user current information. User can edit information : first name, last name, email include back and confirmation button at buttom
A7: TC_ACF_006 | B7: =_xlfn.TEXTJOIN(CHAR(10),,Scenario!$A$23,Scenario!$C$23) -> TS014 Validate the working of 'My Account > Account Information' functionality | C7: Validate account information - current information | D7: Open application,logged in,location is on account information page | E7: 1. Validate result (Validate ER-1) | F7: Not applicable | G7: Current information first name, last name and email address should show correctly
A8: TC_ACF_007 | B8: =_xlfn.TEXTJOIN(CHAR(10),,Scenario!$A$23,Scenario!$C$23) -> TS014 Validate the working of 'My Account > Account Information' functionality | C8: Validate account information - required field visibility | D8: Open application,logged in,location is on account information page | E8: 1. Validate result (Validate ER-1) | F8: Not applicable | G8: Should have shown " * " mark for first name, last name and email
A9: TC_ACF_008 | B9: =_xlfn.TEXTJOIN(CHAR(10),,Scenario!$A$23,Scenario!$C$23) -> TS014 Validate the working of 'My Account > Account Information' functionality | C9: Validate account information - required field functionality | D9: Open application,logged in,location is on account information page | E9: 1. Empty input field -<Refer test data> 2. Click continue 3. Validate result (Validate ER-1) | F9: Field : first name, last name, email address | G9: The deleted field should show message "This field should not be empty"
A10: TC_ACF_009 | B10: =_xlfn.TEXTJOIN(CHAR(10),,Scenario!$A$23,Scenario!$C$23) -> TS014 Validate the working of 'My Account > Account Information' functionality | C10: Validate account information - data modification first name valid | D10: Open application,logged in,location is on account information page | E10: 1. Change text in first name -<Refer test data> 2. Click continue 3. Validate result (Validate ER-1) | F10: First name : John | G10: First name should change to input data
A11: TC_ACF_010 | B11: =_xlfn.TEXTJOIN(CHAR(10),,Scenario!$A$23,Scenario!$C$23) -> TS014 Validate the working of 'My Account > Account Information' functionality | C11: Validate account information - data modification first name invalid characters | D11: Open application,logged in,location is on account information page | E11: 1. Change text in first name -<Refer test data> 2. Click continue 3. Validate result (Validate ER-1) | F11: First name : จอห์น | G11: Only accept english which contain between 1 - 32 characters Show error message "Please use only english characters for first name"
A12: TC_ACF_011 | B12: =_xlfn.TEXTJOIN(CHAR(10),,Scenario!$A$23,Scenario!$C$23) -> TS014 Validate the working of 'My Account > Account Information' functionality | C12: Validate account information - data modification first name invalid size | D12: Open application,logged in,location is on account information page | E12: 1. Change text in first name -<Refer test data> 2. Click continue 3. Validate result (Validate ER-1) | F12: First name : J , name that over 20 characters | G12: Show message "First Name must be between 1 and 32 characters!"
A13: TC_ACF_012 | B13: =_xlfn.TEXTJOIN(CHAR(10),,Scenario!$A$23,Scenario!$C$23) -> TS014 Validate the working of 'My Account > Account Information' functionality | C13: Validate account information - data modification last name valid | D13: Open application,logged in,location is on account information page | E13: 1. Change text in last name -<Refer test data> 2. Click continue 3. Validate result (Validate ER-1) | F13: Last name : Rowel | G13: Last name should change to input data
A14: TC_ACF_013 | B14: =_xlfn.TEXTJOIN(CHAR(10),,Scenario!$A$23,Scenario!$C$23) -> TS014 Validate the working of 'My Account > Account Information' functionality | C14: Validate account information - data modification last name invalid characters | D14: Open application,logged in,location is on account information page | E14: 1. Change text in last name -<Refer test data> 2. Click continue 3. Validate result (Validate ER-1) | F14: Last name : กำเนิด | G14: Only accept english which contain between 1 - 20 characters Show error message "Please use only english characters for last name"
A15: TC_ACF_014 | B15: =_xlfn.TEXTJOIN(CHAR(10),,Scenario!$A$23,Scenario!$C$23) -> TS014 Validate the working of 'My Account > Account Information' functionality | C15: Validate account information - data modification last name invalid size | D15: Open application,logged in,location is on account information page | E15: 1. Change text in last name -<Refer test data> 2. Click continue 3. Validate result (Validate ER-1) | F15: Last name : B , name that over 20 characters | G15: Show message "Last Name must be between 1 and 32 characters!"
... A22: TC_ACF_021 | B22: =_xlfn.TEXTJOIN(CHAR(10),,Scenario!$A$23,Scenario!$C$23) -> TS014 Validate the working of 'My Account > Account Information' functionality | C22: Validate login after user change email address - old email | D22: Open application,logged in,location is on account information page | E22: 1. Change email -<Refer test data> 2. Logout 3. Try to login with old email | F22: New email : John.new@gmail.com Old email : John@gmail.com | G22: Should fail the login and return with warning "Warning:This email was changed from the account please use new email to login"
A23: TC_ACF_022 | B23: =_xlfn.TEXTJOIN(CHAR(10),,Scenario!$A$24,Scenario!$C$24) -> TS015 Validate the working of 'My Account > Change Password' functionality | C23: Validate change password feature - access through account page | D23: Open application,logged in,location is on account information page | E23: 1. Click change your password link under my account section 2. Validate result (Validate ER-1) | F23: Not applicable | G23: Should navigate user to change password page
A24: TC_ACF_023 | B24: =_xlfn.TEXTJOIN(CHAR(10),,Scenario!$A$24,Scenario!$C$24) -> TS015 Validate the working of 'My Account > Change Password' functionality | C24: Validate change password feature - access through quick access | D24: Open application,logged in,location is on any account page | E24: 1. Click password on quick access 2. Validate result (Validate ER-1) | F24: Not applicable | G24: Should navigate user to change password page
A25: TC_ACF_024 | B25: =_xlfn.TEXTJOIN(CHAR(10),,Scenario!$A$24,Scenario!$C$24) -> TS015 Validate the working of 'My Account > Change Password' functionality | C25: Validate change password feature - element | D25: Open application,logged in,location is on change password page | E25: 1. Validate result (Validate ER-1) | F25: Not applicable | G25: Page should show page title "Change Password" have 2 input password and password confirm, back button and continue button
A26: TC_ACF_025 | B26: =_xlfn.TEXTJOIN(CHAR(10),,Scenario!$A$24,Scenario!$C$24) -> TS015 Validate the working of 'My Account > Change Password' functionality | C26: Validate change password feature - required field | D26: Open application,logged in,location is on change password page | E26: 1. Leave password and password confirm empty 2. Click confirm button 3. Validate result (Validate ER-1) | F26: Not applicable | G26: Password and password confirm should has visible "*" mark and did not accept empty input
A27: TC_ACF_026 | B27: =_xlfn.TEXTJOIN(CHAR(10),,Scenario!$A$24,Scenario!$C$24) -> TS015 Validate the working of 'My Account > Change Password' functionality | C27: Validate change password feature - hidden | D27: Open application,logged in,location is on change password page | E27: 1. Input password and password confirm -<Refer test data> 2. Validate reuslt (Validate ER-1) | F27: Password : 123456 Password confirm : 123456 | G27: Password should be hidden
A28: TC_ACF_027 | B28: =_xlfn.TEXTJOIN(CHAR(10),,Scenario!$A$24,Scenario!$C$24) -> TS015 Validate the working of 'My Account > Change Password' functionality | C28: Validate change password feature - show | D28: Open application,logged in,location is on change password page | E28: 1. Input password and password confirm -<Refer test data> 2. Validate reuslt (Validate ER-1) | F28: Password : 123456 Password confirm : 123456 | G28: Should have visible reveal password button | H28: Do not have reveal password button
A29: TC_ACF_028 | B29: =_xlfn.TEXTJOIN(CHAR(10),,Scenario!$A$24,Scenario!$C$24) -> TS015 Validate the working of 'My Account > Change Password' functionality | C29: Validate change password feature - back button | D29: Open application,logged in,location is on change password page | E29: 1. Click back button 2. Validate reuslt (Validate ER-1) | F29: Not applicable | G29: Should navigate user back to account information page
A30: TC_ACF_029 | B30: =_xlfn.TEXTJOIN(CHAR(10),,Scenario!$A$24,Scenario!$C$24) -> TS015 Validate the working of 'My Account > Change Password' functionality | C30: Validate change password feature - continue button | D30: Open application,logged in,location is on change password page | E30: 1. Click back button 2. Validate reuslt (Validate ER-1) | F30: Not applicable | G30: Should visible and locate on buttom right of the password input location
A31: TC_ACF_030 | B31: =_xlfn.TEXTJOIN(CHAR(10),,Scenario!$A$24,Scenario!$C$24) -> TS015 Validate the working of 'My Account > Change Password' functionality | C31: Validate change password feature - change password match | D31: Open application,logged in,location is on change password page | E31: 1. Input password and password confirm -<Refer test data> 2. Click continue 3. Validate reuslt (Validate ER-1) | F31: Password : 123456 Password confirm : 123456 | G31: Should show message "Password change successfully"
A32: TC_ACF_031 | B32: =_xlfn.TEXTJOIN(CHAR(10),,Scenario!$A$24,Scenario!$C$24) -> TS015 Validate the working of 'My Account > Change Password' functionality | C32: Validate change password feature - change password not match | D32: Open application,logged in,location is on change password page | E32: 1. Input password and password confirm -<Refer test data> 2. Click continue 3. Validate reuslt (Validate ER-1) | F32: Password : 123456 Password confirm : 1234567 | G32: Should show message "Both password does not match"
A33: TC_ACF_032 | B33: =_xlfn.TEXTJOIN(CHAR(10),,Scenario!$A$24,Scenario!$C$24) -> TS015 Validate the working of 'My Account > Change Password' functionality | C33: Validate change password feature - change password same as previous password | D33: Open application,logged in,location is on change password page | E33: 1. Input password and password confirm -<Refer test data> 2. Click continue 3. Validate reuslt (Validate ER-1) | F33: Password : 123456 Password confirm : 123456 | G33: Should show message "You cannot use old password as a new password"
A34: TC_ACF_033 | B34: =_xlfn.TEXTJOIN(CHAR(10),,Scenario!$A$24,Scenario!$C$24) -> TS015 Validate the working of 'My Account > Change Password' functionality | C34: Validate change password feature - change password to password that already use in the past | D34: Open application,logged in,location is on change password page | E34: 1. Input password and password confirm -<Refer test data> 2. Click continue 3. Validate reuslt (Validate ER-1) | F34: Password : 123456 Password confirm : 123456 | G34: Should show message "You cannot use old password as a new password"
A35: TC_ACF_034 | B35: =_xlfn.TEXTJOIN(CHAR(10),,Scenario!$A$24,Scenario!$C$24) -> TS015 Validate the working of 'My Account > Change Password' functionality | C35: Validate change password feature - change password successful | D35: Open application,logged in,location is on change password page | E35: 1. Input password and password confirm -<Refer test data> 2. Click continue 3. Validate reuslt (Validate ER-1) | F35: Password : 54321 Password confirm : 54321 | G35: Should show message "Password change successfully"
A36: TC_ACF_035 | B36: =_xlfn.TEXTJOIN(CHAR(10),,Scenario!$A$24,Scenario!$C$24) -> TS015 Validate the working of 'My Account > Change Password' functionality | C36: Validate change password feature - invalid password | D36: Open application,logged in,location is on change password page | E36: 1. Input password and password confirm -<Refer test data> 2. Click continue 3. Validate reuslt (Validate ER-1) | F36: Password : ฟหกด Password confirm : ฟหกด | G36: Should show message "PLease use only english alphabet,number,special characters as your password"
A37: TC_ACF_036 | B37: =_xlfn.TEXTJOIN(CHAR(10),,Scenario!$A$24,Scenario!$C$24) -> TS015 Validate the working of 'My Account > Change Password' functionality | C37: Validate change password feature - login with new password | D37: Open application,have an account,password changed,not logged in | E37: 1. Login with new password -<Refer test data> 2. Validate result (Validate ER-1) | F37: Email : John@gmail.com Password : 54321 | G37: Should successfully loged in
A38: TC_ACF_037 | B38: =_xlfn.TEXTJOIN(CHAR(10),,Scenario!$A$24,Scenario!$C$24) -> TS015 Validate the working of 'My Account > Change Password' functionality | C38: Validate change password feature - login with old password | D38: Open application,have an account,password changed,not logged in | E38: 1. Login with new password -<Refer test data> 2. Validate result (Validate ER-1) | F38: Email : John@gmail.com Password : 123456 | G38: Should fail the login and return with warning "Warning:This password was changed from the account please use new password or reset password"
A39: TC_ACF_038 | B39: =_xlfn.TEXTJOIN(CHAR(10),,Scenario!$A$24,Scenario!$C$24) -> TS015 Validate the working of 'My Account > Change Password' functionality | C39: Validate change password feature - login with previous password | D39: Open application,have an account,password changed,not logged in | E39: 1. Login with new password -<Refer test data> 2. Validate result (Validate ER-1) | F39: Email : John@gmail.com Password : 123456 | G39: Should fail the login and return with warning "Warning:This password was changed from the account please use new password or reset password"
A40: TC_ACF_039 | B40: =_xlfn.TEXTJOIN(CHAR(10),,Scenario!$A$25,Scenario!$C$25) -> TS016 Validate the working of 'My Account Address Book' functionality | C40: Validate access to address book - access through account page | D40: Open application,logged in,enter my account page | E40: 1. Click 'modify your address entries' under my account section 2. Validate result (Valdate ER-1) | F40: Not applicable
A41: TC_ACF_040 | B41: =_xlfn.TEXTJOIN(CHAR(10),,Scenario!$A$25,Scenario!$C$25) -> TS016 Validate the working of 'My Account Address Book' functionality | C41: Validate access to address book - access through quick access | D41: Open application,logged in,location is on any account page | E41: 1. Click 'Address Book' option on quick access 2. Validate result (Validate ER-1) | F41: Not applicable
A42: TC_ACF_041 | B42: =_xlfn.TEXTJOIN(CHAR(10),,Scenario!$A$25,Scenario!$C$25) -> TS016 Validate the working of 'My Account Address Book' functionality | C42: Address book page - element | D42: Open application,logged in,location is on address book page | E42: 1. Validate result (Validate ER-1) | F42: Not applicable | G42: Should contain "Address Book Entries" header,address book information,back button, new address button, quick access section
A43: TC_ACF_042 | B43: =_xlfn.TEXTJOIN(CHAR(10),,Scenario!$A$25,Scenario!$C$25) -> TS016 Validate the working of 'My Account Address Book' functionality | C43: Address book page - no address | D43: Open application,logged in,location is on address book page,has no entry on the list | E43: 1. Validate result (Validate ER-1) | F43: Not applicable | G43: Should show message "You have no addresses in your account." under address book entities section
A44: TC_ACF_043 | B44: =_xlfn.TEXTJOIN(CHAR(10),,Scenario!$A$25,Scenario!$C$25) -> TS016 Validate the working of 'My Account Address Book' functionality | C44: Address book page - have item | D44: Open application,logged in,location is on address book page,has at least one entry on the list | E44: 1. Validate result (Validate ER-1) | F44: Not applicable | G44: Should shown entries by row, have entries data on left side and action button (edit and delete) on the right side
A45: TC_ACF_044 | B45: =_xlfn.TEXTJOIN(CHAR(10),,Scenario!$A$25,Scenario!$C$25) -> TS016 Validate the working of 'My Account Address Book' functionality | C45: Address book page - back button | D45: Open application,logged in,location is on address book page | E45: 1. Click back button 2. Validate reuslt (Validate ER-1) | F45: Not applicable | G45: Should navigate user back to account information page
A46: TC_ACF_045 | B46: =_xlfn.TEXTJOIN(CHAR(10),,Scenario!$A$25,Scenario!$C$25) -> TS016 Validate the working of 'My Account Address Book' functionality | C46: Address book page - delete address | D46: Open application,logged in,location is on address book page,has at least one entry on the list | E46: 1. Click delete button on entry -<Refer test data> 2. Validate result (Validate ER-1) | F46: Entries : any entries | G46: Selected entry should be removed
...

Sheet Search
A1: Test Case ID | B1: Test Scenario | C1: Test Case Title | D1: Pre-requisites | E1: Test Steps | F1: Test Data | G1: Expected Result (ER) | H1: Actual Result | I1: Priority | J1: Result | K1: Comments
A2: TC_S_001 | B2: =_xlfn.TEXTJOIN(CHAR(10),,Scenario!$A$14,Scenario!$C$14) -> TS005 Validate the working of 'Search' functionality | C2: Validate search - placeholder | D2: Open application | E2: 1. Validate result (ER-1) | F2: Not applicable | G2: Search bar should have placeholder "Search"
A3: TC_S_002 | B3: =_xlfn.TEXTJOIN(CHAR(10),,Scenario!$A$14,Scenario!$C$14) -> TS005 Validate the working of 'Search' functionality | C3: Validate search - empty | D3: Open application | E3: 1. Leave input empty 2. Click search icon | F3: Not applicable | G3: Should show message "Please enter your search criteria"
A4: TC_S_003 | B4: =_xlfn.TEXTJOIN(CHAR(10),,Scenario!$A$14,Scenario!$C$14) -> TS005 Validate the working of 'Search' functionality | C4: Validate search - valid | D4: Open application | E4: 1. Input search criteria 2. Click search icon 3. Validate result (ER-1) | F4: Iphone | G4: Should show search result on current page based on search criteria
A5: TC_S_004 | B5: =_xlfn.TEXTJOIN(CHAR(10),,Scenario!$A$14,Scenario!$C$14) -> TS005 Validate the working of 'Search' functionality | C5: Validate search - exact | D5: Open application | E5: 1. Input search criteria 2. Click search icon 3. Validate result (ER-1) | F5: Apple cinima 30" | G5: Search results should at least show the exact match product
A6: TC_S_005 | B6: =_xlfn.TEXTJOIN(CHAR(10),,Scenario!$A$14,Scenario!$C$14) -> TS005 Validate the working of 'Search' functionality | C6: Validate search - partial | D6: Open application | E6: 1. Input search criteria 2. Click search icon 3. Validate result (ER-1) | F6: Apple cini | G6: Should be able to find similar item when match with partial word
A7: TC_S_006 | B7: =_xlfn.TEXTJOIN(CHAR(10),,Scenario!$A$14,Scenario!$C$14) -> TS005 Validate the working of 'Search' functionality | C7: Validate search - product name | D7: Open application | E7: 1. Input search criteria 2. Click search icon 3. Validate result (ER-1) | F7: Iphone14 | G7: Search result should be able to find item when match by product name
A8: TC_S_007 | B8: =_xlfn.TEXTJOIN(CHAR(10),,Scenario!$A$14,Scenario!$C$14) -> TS005 Validate the working of 'Search' functionality | C8: Validate search - brand name | D8: Open application | E8: 1. Input search criteria 2. Click search icon 3. Validate result (ER-1) | F8: Apple | G8: Search result should be able to find item when match by brand name
A9: TC_S_008 | B9: =_xlfn.TEXTJOIN(CHAR(10),,Scenario!$A$14,Scenario!$C$14) -> TS005 Validate the working of 'Search' functionality | C9: Validate search - product cat | D9: Open application | E9: 1. Input search criteria 2. Click search icon 3. Validate result (ER-1) | F9: Tablets | G9: Search result should be able to find item when match by product category
A10: TC_S_009 | B10: =_xlfn.TEXTJOIN(CHAR(10),,Scenario!$A$14,Scenario!$C$14) -> TS005 Validate the working of 'Search' functionality | C10: Validate search - description | D10: Open application | E10: 1. Input search criteria 2. Click search icon 3. Validate result (ER-1) | F10: 4k | G10: Search result should be able to find item when match by product description
A11: TC_S_010 | B11: =_xlfn.TEXTJOIN(CHAR(10),,Scenario!$A$14,Scenario!$C$14) -> TS005 Validate the working of 'Search' functionality | C11: Validate search - sub cat | D11: Open application | E11: 1. Input search criteria 2. Click search icon 3. Validate result (ER-1) | F11: PC | G11: Search result should be able to find item when match by product sub category
A12: TC_S_011 | B12: =_xlfn.TEXTJOIN(CHAR(10),,Scenario!$A$14,Scenario!$C$14) -> TS005 Validate the working of 'Search' functionality | C12: Validate search - availability | D12: Open application | E12: 1. Input search criteria 2. Click search icon 3. Validate result (ER-1) | F12: Available | G12: Search result should be able to find item when match by availability
A13: TC_S_012 | B13: =_xlfn.TEXTJOIN(CHAR(10),,Scenario!A14,Scenario!C14) -> TS005 Validate the working of 'Search' functionality | C13: Validate search - character boundary | D13: Open application | E13: 1. Input search criteria 2. Click search icon 3. Validate result (ER-1) | F13: accept only 2-255 characters : criteria : 4k -> result : accept criteria : 4 or any input that over 255 characters -> result : reject | G13: Search result only accept input that contain between 2 - 255 characters,If not warning message should display "Only accept 2 - 255 characters in search criteria"
A14: TC_S_013 | B14: =_xlfn.TEXTJOIN(CHAR(10),,Scenario!A14,Scenario!C14) -> TS005 Validate the working of 'Search' functionality | C14: Validate search - found | D14: Open application | E14: 1. Input search criteria 2. Click search icon 3. Validate result (ER-1) | F14: Canon EOS 5D | G14: Search result will show item in result area
A15: TC_S_014 | B15: =_xlfn.TEXTJOIN(CHAR(10),,Scenario!A14,Scenario!C14) -> TS005 Validate the working of 'Search' functionality | C15: Validate search - found multiple | D15: Open application | E15: 1. Input search criteria 2. Click search icon 3. Validate result (ER-1) | F15: Apple | G15: Search result will show item in result area
A16: TC_S_015 | B16: =_xlfn.TEXTJOIN(CHAR(10),,Scenario!A14,Scenario!C14) -> TS005 Validate the working of 'Search' functionality | C16: Validate search - not found | D16: Open application | E16: 1. Input search criteria 2. Click search icon 3. Validate result (ER-1) | F16: Hammock | G16: Search result will show message "criteria is not found"
A17: TC_S_016 | B17: =_xlfn.TEXTJOIN(CHAR(10),,Scenario!A14,Scenario!C14) -> TS005 Validate the working of 'Search' functionality | C17: Validate search - select subcat filter | D17: Open application,Search item(found) | E17: 1. Input search criteria -<refer test data - criteria> 2. Click search icon 3. Select sub category filter -<refer test data - sub category> 4. Validate result (ER-1) | F17: criteria : apple sub category : tablets | G17: Search result will only show item that match selected sub category
A18: TC_S_017 | B18: =_xlfn.TEXTJOIN(CHAR(10),,Scenario!A14,Scenario!C14) -> TS005 Validate the working of 'Search' functionality | C18: Validate list view | D18: Open application,Search item(found) | E18: 1. Click list view icon 2. Validate result (ER-1) | F18: Not applicable | G18: Search result will show item in list
A19: TC_S_018 | B19: =_xlfn.TEXTJOIN(CHAR(10),,Scenario!A14,Scenario!C14) -> TS005 Validate the working of 'Search' functionality | C19: Validate grid view | D19: Open application,Search item(found) | E19: 1. Click grid view icon 2. Validate result (ER-1) | F19: Not applicable | G19: Search result will show item in grid
A20: TC_S_019 | B20: =_xlfn.TEXTJOIN(CHAR(10),,Scenario!A14,Scenario!C14) -> TS005 Validate the working of 'Search' functionality | C20: Validate sorting | D20: Open application,Search item(found) | E20: 1. Click sort item icon 2. Select sorting type -<Refer test data> 3. Validate result (ER-1) | F20: Ascending | G20: Search result will sort by selected sorting type
A21: TC_S_020 | B21: =_xlfn.TEXTJOIN(CHAR(10),,Scenario!A14,Scenario!C14) -> TS005 Validate the working of 'Search' functionality | C21: Validate item display (quantity) | D21: Open application,Search item(found) | E21: 1. Click dropdown "show" in refine search area 2. Select quantity -<Refer test data> 3. Validate result (ER-1) | F21: 15 | G21: Search result will only show item by selected quantity per page
A22: TC_S_021 | B22: =_xlfn.TEXTJOIN(CHAR(10),,Scenario!A14,Scenario!C14) -> TS005 Validate the working of 'Search' functionality | C22: Validate item display (quantity) - over limit | D22: Open application,Search item(found), result quantity is more than selected item display | E22: 1. Click dropdown "show" in refine search area 2. Select quantity -<Refer test data> 3. Validate result (ER-1) | F22: Not applicable | G22: The exeed items will split in to page(s)
A23: TC_S_022 | B23: =_xlfn.TEXTJOIN(CHAR(10),,Scenario!A14,Scenario!C14) -> TS005 Validate the working of 'Search' functionality | C23: Validate item display (quantity) - below limit | D23: Open application,Search item(found), result quantity is less than selected item display | E23: 1. Click dropdown "show" in refine search area 2. Select quantity -<Refer test data> 3. Validate result (ER-1) | F23: Not applicable | G23: Search result will only show in one page
A24: TC_S_023 | B24: =_xlfn.TEXTJOIN(CHAR(10),,Scenario!A14,Scenario!C14) -> TS005 Validate the working of 'Search' functionality | C24: Validate navigate compare | D24: Open application,Search item(found) | E24: 1. Click compare symbol on item 2. Validate result (ER-1) | F24: Not applicable | G24: Selected item will be add to compare list

Sheet Product Comparison
A1: Test Case ID | B1: Test Scenario | C1: Test Case Title | D1: Pre-requisites | E1: Test Steps | F1: Test Data | G1: Expected Result (ER) | H1: Actual Result | I1: Priority | J1: Result | K1: Comments
A2: TC_PC_001 | B2: =_xlfn.TEXTJOIN(CHAR(10),,Scenario!A15,Scenario!C15) -> TS006 Validate the working of 'Product compare' functionality | C2: Product comparison - default | D2: Open application,enter product comparison page
A3: TC_PC_002 | B3: =_xlfn.TEXTJOIN(CHAR(10),,Scenario!A15,Scenario!C15) -> TS006 Validate the working of 'Product compare' functionality | C3: Product comparison - empty | D3: Open application,enter product comparison page
A4: TC_PC_003 | B4: =_xlfn.TEXTJOIN(CHAR(10),,Scenario!A15,Scenario!C15) -> TS006 Validate the working of 'Product compare' functionality | C4: Product comparison - limit | D4: Open application,on any product page
A5: TC_PC_004 | B5: =_xlfn.TEXTJOIN(CHAR(10),,Scenario!A15,Scenario!C15) -> TS006 Validate the working of 'Product compare' functionality | C5: Product comparison - duplicate | D5: Open application,on any product page
A6: TC_PC_005 | B6: =_xlfn.TEXTJOIN(CHAR(10),,Scenario!A15,Scenario!C15) -> TS006 Validate the working of 'Product compare' functionality | C6: Product comparison - remove | D6: Open application,enter product comparison page
A7: TC_PC_006 | B7: =_xlfn.TEXTJOIN(CHAR(10),,Scenario!A15,Scenario!C15) -> TS006 Validate the working of 'Product compare' functionality | C7: Product comparison - view detailed product | D7: Open application,enter product comparison page
A8: TC_PC_007 | B8: =_xlfn.TEXTJOIN(CHAR(10),,Scenario!A15,Scenario!C15) -> TS006 Validate the working of 'Product compare' functionality | C8: Product comparison - add item to cart | D8: Open application,enter product comparison page

Sheet HomePage
A1: Test Case ID | B1: Test Scenario | C1: Test Case Title | D1: Pre-requisites | E1: Test Steps | F1: Test Data | G1: Expected Result (ER) | H1: Actual Result | I1: Priority | J1: Result | K1: Comments
A2: TC_HP_001 | B2: =_xlfn.TEXTJOIN(CHAR(10),,Scenario!A20,Scenario!C20) -> TS011 Validate the working of 'Home page' functionality | C2: Validate top menu | D2: Open https://demo.opencart.com | E2: 1. Validate that top menu is displayed correctly (Validate ER-1) | F2: No Applicable | G2: 1) Top menu should displayed at top of the page under header which contain top parent categories of products as following : Desktops Laptop & Notebooks Components Tablets Software Phone & PDAs Cameras MP3 Players
A3: TC_HP_002 | B3: =_xlfn.TEXTJOIN(CHAR(10),,Scenario!A20,Scenario!C20) -> TS011 Validate the working of 'Home page' functionality | C3: Validate 'Direct back to home page' from product page | D3: Open https://demo.opencart.com | E3: 1. Click on product from 'Featured products - <Refer Test Data> 2. Wait for application to redirect user to product page (Validate ER-1) 3. Click store logo at top right corner on header (Validate ER-2) | F3: MacBook | G3: 1) User should redirect to product page 2) User should redirect back to home page
A4: TC_HP_003 | B4: =_xlfn.TEXTJOIN(CHAR(10),,Scenario!A20,Scenario!C20) -> TS011 Validate the working of 'Home page' functionality | C4: Validate 'Direct back to home page' from shopping cart page | D4: Open https://demo.opencart.com | E4: 1. Click 'Shopping Cart' (Validate ER-1) 2. Click store logo at top right corner on header (Validate ER-2) | F4: No Applicable | G4: 1) User should redirect to shopping cart page 2) User should redirect back to home page
A5: TC_HP_004 | B5: =_xlfn.TEXTJOIN(CHAR(10),,Scenario!A20,Scenario!C20) -> TS011 Validate the working of 'Home page' functionality | C5: Slideshow display image | D5: Open https://demo.opencart.com | E5: 1. Validate display image (Validate ER-1) | F5: No Applicable | G5: 1) All Selected images will appear in slideshow
A6: TC_HP_005 | B6: =_xlfn.TEXTJOIN(CHAR(10),,Scenario!A20,Scenario!C20) -> TS011 Validate the working of 'Home page' functionality | C6: Slideshow automatically change image | D6: Open https://demo.opencart.com | E6: 1. Wait a certain amount of time (Validate ER-1) | F6: No Applicable | G6: 1) image in slidesohw should shift to the next one
A7: TC_HP_006 | B7: =_xlfn.TEXTJOIN(CHAR(10),,Scenario!A20,Scenario!C20) -> TS011 Validate the working of 'Home page' functionality | C7: Slideshow manually change image | D7: Open https://demo.opencart.com | E7: 1. Validate display image (Validate ER-1) 2. Select another dot under image (Validate ER-2) | F7: No Applicable | G7: 1) image should display correctly 2) image should shift to the selected one
A8: TC_HP_007 | B8: =_xlfn.TEXTJOIN(CHAR(10),,Scenario!A20,Scenario!C20) -> TS011 Validate the working of 'Home page' functionality | C8: Slideshow select product | D8: Open https://demo.opencart.com | E8: 1. Click display image - <Refer Test Data> 2. Validate navigation result (Validate ER-1) | F8: Slideshow image : 'MacBook' | G8: 1) User should redirect to product page of selected product
A9: TC_HP_008 | B9: =_xlfn.TEXTJOIN(CHAR(10),,Scenario!A20,Scenario!C20) -> TS011 Validate the working of 'Home page' functionality | C9: Validate 'Featured products' details | D9: Open https://demo.opencart.com | E9: 1. Validate featured product display correctly (Validate ER-1) | F9: No Applicable | G9: 1) Featured product should display under slideshow contain following elements: 1. Item Box 2. Product image 3. Product name 4. Product price 5. 'ADD TO CART' button 6. 'Wish list' button 7. 'Compare product' button
